#VRML_SIM R2019a utf8
WorldInfo {
}
Viewpoint {
  orientation -0.6962305262205254 0.7035569222466851 0.14237524896365308 0.5192163566656849
  position 0.877874610235889 1.300555113838683 1.6528530008821973
}
TexturedBackground {
}
TexturedBackgroundLight {
}
Floor {
}
Solid {
  translation 0 0.25 0
  children [
    Shape {
      appearance PBRAppearance {
        baseColor 0.12549019607843137 0.2901960784313726 0.5294117647058824
        roughness 1
        metalness 0
      }
      geometry Cylinder {
        height 0.5
        radius 0.05
      }
    }
    HingeJoint {
      jointParameters HingeJointParameters {
        position -1245.907687182215
        axis 0 1 0
        anchor 0 0.255 0
      }
      endPoint Solid {
        translation 0 0.255 0
        rotation 0 -0.9999999999999999 0 1.8369963606569908
        children [
          Shape {
            appearance PBRAppearance {
              baseColor 0.8 0 0
              roughness 1
              metalness 0
            }
            geometry Box {
              size 0.8 0.01 0.1
            }
          }
        ]
        physics Physics {
        }
        linearVelocity -3.95252516672997e-323 1.0800493412030032e-15 1.48219693752374e-323
        angularVelocity 4.94065645841247e-323 -11.099448095482472 -1.67982319586024e-322
      }
    }
  ]
}
