#VRML_SIM R2019a utf8
WorldInfo {
}
Viewpoint {
  orientation -0.24429161693559076 0.9342199351687386 0.2599129058517725 1.6767793970968259
  position 1.922259579280427 1.634006028540814 -0.37947835143738434
}
TexturedBackground {
}
TexturedBackgroundLight {
}
Floor {
}
Solid {
  translation 0 0.25 0
  children [
    Shape {
      appearance PBRAppearance {
        baseColor 0.12549019607843137 0.2901960784313726 0.5294117647058824
        roughness 1
        metalness 0
      }
      geometry Cylinder {
        height 0.5
        radius 0.05
      }
    }
    HingeJoint {
      jointParameters HingeJointParameters {
        position -1245.907687182215
        axis 0 1 0
        anchor 0 0.255 0
        staticFriction 0.2
      }
      endPoint Solid {
        translation 0 0.255 0
        rotation 0 -0.9999999999999999 0 1.8369963606569908
        children [
          Shape {
            appearance PBRAppearance {
              baseColor 0.8 0 0
              roughness 1
              metalness 0
            }
            geometry Box {
              size 0.8 0.01 0.1
            }
          }
        ]
        physics Physics {
        }
      }
    }
  ]
}
