#VRML_SIM R2019a utf8
WorldInfo {
}
Viewpoint {
  orientation -0.9799584830645712 -0.1903047826412391 -0.0588681677450152 0.6115270097779496
  position -0.1637970380676404 1.3360880711884746 1.524136924514699
}
TexturedBackground {
}
TexturedBackgroundLight {
}
Floor {
}
Solid {
  translation -0.03997467533380006 0.2500000000000002 -0.1647045055768479
  children [
    Shape {
      appearance PBRAppearance {
        baseColor 0.12549019607843137 0.2901960784313726 0.5294117647058824
        roughness 1
        metalness 0
      }
      geometry Cylinder {
        height 0.5
        radius 0.05
      }
    }
    HingeJoint {
      jointParameters HingeJointParameters {
        position -1293.8136755034952
        axis 0 1 0
        anchor 0 0.255 0
        staticFriction 0.2
      }
      endPoint Solid {
        translation 0.03731470046731902 0.25496802264899976 -0.022502543242944338
        rotation 8.238475927812883e-06 -0.9999999999620198 2.8439196665887133e-06 5.898234104462647
        children [
          Shape {
            appearance PBRAppearance {
              baseColor 0.8 0 0
              roughness 1
              metalness 0
            }
            geometry Box {
              size 0.8 0.01 0.1
            }
          }
        ]
        physics Physics {
        }
        linearVelocity 0.06310225382682208 -5.544416693317916e-10 0.0841306710305986
        angularVelocity 3.6456142846262605e-09 -2.382642677249315 -1.858316562833504e-08
      }
    }
    HingeJoint {
      jointParameters HingeJointParameters {
        position 2825.097796512122
        axis 0 0 1
        anchor 0 0 0.055
      }
      endPoint Solid {
        translation 0 0 0.055
        rotation 0 0 -1 2.3355917186919832
        children [
          Shape {
            appearance PBRAppearance {
              baseColor 0.9372549019607843 0.1607843137254902 0.1607843137254902
              roughness 1
              metalness 0
            }
            geometry Box {
              size 0.1 0.03 0.01
            }
          }
        ]
        name "solid(1)"
        physics Physics {
        }
        linearVelocity -5.060318857435774e-19 -2.699739200278999e-16 0
        angularVelocity 0 0 3.0946008968496197
      }
    }
  ]
}
