#VRML_SIM R2019a utf8
WorldInfo {
}
Viewpoint {
  orientation -0.6650478245550326 -0.7400058777890871 -0.10051214798332064 0.40292898324059157
  position -0.3389324466126279 0.5154055165807777 1.3875857808881553
}
TexturedBackground {
}
TexturedBackgroundLight {
}
Floor {
}
Solid {
  translation -0.03997467533380006 0.2500000000000002 -0.1647045055768479
  children [
    Shape {
      appearance PBRAppearance {
        baseColor 0.12549019607843137 0.2901960784313726 0.5294117647058824
        roughness 1
        metalness 0
      }
      geometry Cylinder {
        height 0.5
        radius 0.05
      }
    }
    HingeJoint {
      jointParameters HingeJointParameters {
        position -1247.0934346887086
        axis 0 1 0
        anchor 0 0.255 0
        staticFriction 0.2
      }
      endPoint Solid {
        translation -0.043154337152984834 0.25496802264899976 0.006037756889179364
        rotation -8.48913560277402e-07 0.9999999999986101 1.43495700198226e-06 3.1228948672322163
        children [
          Shape {
            appearance PBRAppearance {
              baseColor 0.8 0 0
              roughness 1
              metalness 0
            }
            geometry Box {
              size 0.8 0.01 0.1
            }
          }
        ]
        physics Physics {
        }
        linearVelocity 1.6739969744440192e-13 -1.2162241264946787e-07 -2.3277885905862923e-14
        angularVelocity 7.326347385470463e-10 8.111188659011894e-23 5.236442474901115e-09
      }
    }
    HingeJoint {
      jointParameters HingeJointParameters {
        position 2746.371149696405
        axis 0 0 1
        anchor 0 0 0.055
      }
      endPoint Solid {
        translation 0 0 0.055
        rotation 0 0 -1 5.664014848253722
        children [
          Shape {
            appearance PBRAppearance {
              baseColor 0.9372549019607843 0.1607843137254902 0.1607843137254902
              roughness 1
              metalness 0
            }
            geometry Box {
              size 0.1 0.03 0.01
            }
          }
        ]
        name "solid(1)"
        physics Physics {
        }
        linearVelocity 1.624088942506683e-18 2.416319548545364e-16 1.734723475976807e-16
        angularVelocity 2.96439387504748e-323 8.89318162514244e-323 3.0946008968496197
      }
    }
  ]
}
